[20/Oct/2017 21:55:23] ERROR [django.request:284] Internal Server Error: /columbus-master/cgi-bin/verify.py
Traceback (most recent call last):
  File "/s/bach/j/under/mroseliu/.local/lib/python2.7/site-packages/django/core/handlers/base.py", line 134, in get_response
    resolver_match = resolver.resolve(request.path_info)
  File "/s/bach/j/under/mroseliu/.local/lib/python2.7/site-packages/django/core/urlresolvers.py", line 374, in resolve
    for pattern in self.url_patterns:
  File "/s/bach/j/under/mroseliu/.local/lib/python2.7/site-packages/django/utils/functional.py", line 33, in __get__
    res = instance.__dict__[self.name] = self.func(instance)
  File "/s/bach/j/under/mroseliu/.local/lib/python2.7/site-packages/django/core/urlresolvers.py", line 417, in url_patterns
    patterns = getattr(self.urlconf_module, "urlpatterns", self.urlconf_module)
  File "/s/bach/j/under/mroseliu/.local/lib/python2.7/site-packages/django/utils/functional.py", line 33, in __get__
    res = instance.__dict__[self.name] = self.func(instance)
  File "/s/bach/j/under/mroseliu/.local/lib/python2.7/site-packages/django/core/urlresolvers.py", line 410, in urlconf_module
    return import_module(self.urlconf_name)
  File "/usr/lib64/python2.7/importlib/__init__.py", line 37, in import_module
    __import__(name)
  File "/s/bach/j/under/mroseliu/.local/lib/python2.7/site-packages/columbus/urls.py", line 20, in <module>
    from pyedf.views import *
  File "/s/bach/j/under/mroseliu/.local/lib/python2.7/site-packages/pyedf/views.py", line 14, in <module>
    from colorker.service import bigquery, drive, fusiontables, gee
  File "/s/bach/j/under/mroseliu/.local/lib/python2.7/site-packages/colorker/service/bigquery.py", line 17, in <module>
    from colorker.security import CredentialManager
  File "/s/bach/j/under/mroseliu/.local/lib/python2.7/site-packages/colorker/security.py", line 7, in <module>
    import ee
  File "/s/bach/j/under/mroseliu/.local/lib/python2.7/site-packages/ee/__init__.py", line 18, in <module>
    from . import batch
  File "/s/bach/j/under/mroseliu/.local/lib/python2.7/site-packages/ee/batch.py", line 15, in <module>
    from . import data
  File "/s/bach/j/under/mroseliu/.local/lib/python2.7/site-packages/ee/data.py", line 14, in <module>
    import httplib2
ImportError: No module named httplib2
[20/Oct/2017 21:55:24] ERROR [django.request:284] Internal Server Error: /favicon.ico
Traceback (most recent call last):
  File "/s/bach/j/under/mroseliu/.local/lib/python2.7/site-packages/django/core/handlers/base.py", line 134, in get_response
    resolver_match = resolver.resolve(request.path_info)
  File "/s/bach/j/under/mroseliu/.local/lib/python2.7/site-packages/django/core/urlresolvers.py", line 374, in resolve
    for pattern in self.url_patterns:
  File "/s/bach/j/under/mroseliu/.local/lib/python2.7/site-packages/django/utils/functional.py", line 33, in __get__
    res = instance.__dict__[self.name] = self.func(instance)
  File "/s/bach/j/under/mroseliu/.local/lib/python2.7/site-packages/django/core/urlresolvers.py", line 417, in url_patterns
    patterns = getattr(self.urlconf_module, "urlpatterns", self.urlconf_module)
  File "/s/bach/j/under/mroseliu/.local/lib/python2.7/site-packages/django/utils/functional.py", line 33, in __get__
    res = instance.__dict__[self.name] = self.func(instance)
  File "/s/bach/j/under/mroseliu/.local/lib/python2.7/site-packages/django/core/urlresolvers.py", line 410, in urlconf_module
    return import_module(self.urlconf_name)
  File "/usr/lib64/python2.7/importlib/__init__.py", line 37, in import_module
    __import__(name)
  File "/s/bach/j/under/mroseliu/.local/lib/python2.7/site-packages/columbus/urls.py", line 20, in <module>
    from pyedf.views import *
  File "/s/bach/j/under/mroseliu/.local/lib/python2.7/site-packages/pyedf/views.py", line 14, in <module>
    from colorker.service import bigquery, drive, fusiontables, gee
  File "/s/bach/j/under/mroseliu/.local/lib/python2.7/site-packages/colorker/service/bigquery.py", line 17, in <module>
    from colorker.security import CredentialManager
  File "/s/bach/j/under/mroseliu/.local/lib/python2.7/site-packages/colorker/security.py", line 7, in <module>
    import ee
  File "/s/bach/j/under/mroseliu/.local/lib/python2.7/site-packages/ee/__init__.py", line 18, in <module>
    from . import batch
  File "/s/bach/j/under/mroseliu/.local/lib/python2.7/site-packages/ee/batch.py", line 15, in <module>
    from . import data
  File "/s/bach/j/under/mroseliu/.local/lib/python2.7/site-packages/ee/data.py", line 14, in <module>
    import httplib2
ImportError: No module named httplib2
[20/Oct/2017 21:55:58] ERROR [django.request:284] Internal Server Error: /login.html
Traceback (most recent call last):
  File "/s/bach/j/under/mroseliu/.local/lib/python2.7/site-packages/django/core/handlers/base.py", line 134, in get_response
    resolver_match = resolver.resolve(request.path_info)
  File "/s/bach/j/under/mroseliu/.local/lib/python2.7/site-packages/django/core/urlresolvers.py", line 374, in resolve
    for pattern in self.url_patterns:
  File "/s/bach/j/under/mroseliu/.local/lib/python2.7/site-packages/django/utils/functional.py", line 33, in __get__
    res = instance.__dict__[self.name] = self.func(instance)
  File "/s/bach/j/under/mroseliu/.local/lib/python2.7/site-packages/django/core/urlresolvers.py", line 417, in url_patterns
    patterns = getattr(self.urlconf_module, "urlpatterns", self.urlconf_module)
  File "/s/bach/j/under/mroseliu/.local/lib/python2.7/site-packages/django/utils/functional.py", line 33, in __get__
    res = instance.__dict__[self.name] = self.func(instance)
  File "/s/bach/j/under/mroseliu/.local/lib/python2.7/site-packages/django/core/urlresolvers.py", line 410, in urlconf_module
    return import_module(self.urlconf_name)
  File "/usr/lib64/python2.7/importlib/__init__.py", line 37, in import_module
    __import__(name)
  File "/s/bach/j/under/mroseliu/.local/lib/python2.7/site-packages/columbus/urls.py", line 20, in <module>
    from pyedf.views import *
  File "/s/bach/j/under/mroseliu/.local/lib/python2.7/site-packages/pyedf/views.py", line 14, in <module>
    from colorker.service import bigquery, drive, fusiontables, gee
  File "/s/bach/j/under/mroseliu/.local/lib/python2.7/site-packages/colorker/service/bigquery.py", line 17, in <module>
    from colorker.security import CredentialManager
  File "/s/bach/j/under/mroseliu/.local/lib/python2.7/site-packages/colorker/security.py", line 7, in <module>
    import ee
  File "/s/bach/j/under/mroseliu/.local/lib/python2.7/site-packages/ee/__init__.py", line 18, in <module>
    from . import batch
  File "/s/bach/j/under/mroseliu/.local/lib/python2.7/site-packages/ee/batch.py", line 15, in <module>
    from . import data
  File "/s/bach/j/under/mroseliu/.local/lib/python2.7/site-packages/ee/data.py", line 14, in <module>
    import httplib2
ImportError: No module named httplib2
[20/Oct/2017 21:55:58] ERROR [django.request:284] Internal Server Error: /favicon.ico
Traceback (most recent call last):
  File "/s/bach/j/under/mroseliu/.local/lib/python2.7/site-packages/django/core/handlers/base.py", line 134, in get_response
    resolver_match = resolver.resolve(request.path_info)
  File "/s/bach/j/under/mroseliu/.local/lib/python2.7/site-packages/django/core/urlresolvers.py", line 374, in resolve
    for pattern in self.url_patterns:
  File "/s/bach/j/under/mroseliu/.local/lib/python2.7/site-packages/django/utils/functional.py", line 33, in __get__
    res = instance.__dict__[self.name] = self.func(instance)
  File "/s/bach/j/under/mroseliu/.local/lib/python2.7/site-packages/django/core/urlresolvers.py", line 417, in url_patterns
    patterns = getattr(self.urlconf_module, "urlpatterns", self.urlconf_module)
  File "/s/bach/j/under/mroseliu/.local/lib/python2.7/site-packages/django/utils/functional.py", line 33, in __get__
    res = instance.__dict__[self.name] = self.func(instance)
  File "/s/bach/j/under/mroseliu/.local/lib/python2.7/site-packages/django/core/urlresolvers.py", line 410, in urlconf_module
    return import_module(self.urlconf_name)
  File "/usr/lib64/python2.7/importlib/__init__.py", line 37, in import_module
    __import__(name)
  File "/s/bach/j/under/mroseliu/.local/lib/python2.7/site-packages/columbus/urls.py", line 20, in <module>
    from pyedf.views import *
  File "/s/bach/j/under/mroseliu/.local/lib/python2.7/site-packages/pyedf/views.py", line 14, in <module>
    from colorker.service import bigquery, drive, fusiontables, gee
  File "/s/bach/j/under/mroseliu/.local/lib/python2.7/site-packages/colorker/service/bigquery.py", line 17, in <module>
    from colorker.security import CredentialManager
  File "/s/bach/j/under/mroseliu/.local/lib/python2.7/site-packages/colorker/security.py", line 7, in <module>
    import ee
  File "/s/bach/j/under/mroseliu/.local/lib/python2.7/site-packages/ee/__init__.py", line 18, in <module>
    from . import batch
  File "/s/bach/j/under/mroseliu/.local/lib/python2.7/site-packages/ee/batch.py", line 15, in <module>
    from . import data
  File "/s/bach/j/under/mroseliu/.local/lib/python2.7/site-packages/ee/data.py", line 14, in <module>
    import httplib2
ImportError: No module named httplib2
[20/Oct/2017 21:56:14] ERROR [django.request:284] Internal Server Error: /favicon.ico
Traceback (most recent call last):
  File "/s/bach/j/under/mroseliu/.local/lib/python2.7/site-packages/django/core/handlers/base.py", line 134, in get_response
    resolver_match = resolver.resolve(request.path_info)
  File "/s/bach/j/under/mroseliu/.local/lib/python2.7/site-packages/django/core/urlresolvers.py", line 374, in resolve
    for pattern in self.url_patterns:
  File "/s/bach/j/under/mroseliu/.local/lib/python2.7/site-packages/django/utils/functional.py", line 33, in __get__
    res = instance.__dict__[self.name] = self.func(instance)
  File "/s/bach/j/under/mroseliu/.local/lib/python2.7/site-packages/django/core/urlresolvers.py", line 417, in url_patterns
    patterns = getattr(self.urlconf_module, "urlpatterns", self.urlconf_module)
  File "/s/bach/j/under/mroseliu/.local/lib/python2.7/site-packages/django/utils/functional.py", line 33, in __get__
    res = instance.__dict__[self.name] = self.func(instance)
  File "/s/bach/j/under/mroseliu/.local/lib/python2.7/site-packages/django/core/urlresolvers.py", line 410, in urlconf_module
    return import_module(self.urlconf_name)
  File "/usr/lib64/python2.7/importlib/__init__.py", line 37, in import_module
    __import__(name)
  File "/s/bach/j/under/mroseliu/.local/lib/python2.7/site-packages/columbus/urls.py", line 20, in <module>
    from pyedf.views import *
  File "/s/bach/j/under/mroseliu/.local/lib/python2.7/site-packages/pyedf/views.py", line 14, in <module>
    from colorker.service import bigquery, drive, fusiontables, gee
  File "/s/bach/j/under/mroseliu/.local/lib/python2.7/site-packages/colorker/service/bigquery.py", line 17, in <module>
    from colorker.security import CredentialManager
  File "/s/bach/j/under/mroseliu/.local/lib/python2.7/site-packages/colorker/security.py", line 7, in <module>
    import ee
  File "/s/bach/j/under/mroseliu/.local/lib/python2.7/site-packages/ee/__init__.py", line 18, in <module>
    from . import batch
  File "/s/bach/j/under/mroseliu/.local/lib/python2.7/site-packages/ee/batch.py", line 15, in <module>
    from . import data
  File "/s/bach/j/under/mroseliu/.local/lib/python2.7/site-packages/ee/data.py", line 14, in <module>
    import httplib2
ImportError: No module named httplib2
[20/Oct/2017 21:56:15] ERROR [django.request:284] Internal Server Error: /
Traceback (most recent call last):
  File "/s/bach/j/under/mroseliu/.local/lib/python2.7/site-packages/django/core/handlers/base.py", line 134, in get_response
    resolver_match = resolver.resolve(request.path_info)
  File "/s/bach/j/under/mroseliu/.local/lib/python2.7/site-packages/django/core/urlresolvers.py", line 374, in resolve
    for pattern in self.url_patterns:
  File "/s/bach/j/under/mroseliu/.local/lib/python2.7/site-packages/django/utils/functional.py", line 33, in __get__
    res = instance.__dict__[self.name] = self.func(instance)
  File "/s/bach/j/under/mroseliu/.local/lib/python2.7/site-packages/django/core/urlresolvers.py", line 417, in url_patterns
    patterns = getattr(self.urlconf_module, "urlpatterns", self.urlconf_module)
  File "/s/bach/j/under/mroseliu/.local/lib/python2.7/site-packages/django/utils/functional.py", line 33, in __get__
    res = instance.__dict__[self.name] = self.func(instance)
  File "/s/bach/j/under/mroseliu/.local/lib/python2.7/site-packages/django/core/urlresolvers.py", line 410, in urlconf_module
    return import_module(self.urlconf_name)
  File "/usr/lib64/python2.7/importlib/__init__.py", line 37, in import_module
    __import__(name)
  File "/s/bach/j/under/mroseliu/.local/lib/python2.7/site-packages/columbus/urls.py", line 20, in <module>
    from pyedf.views import *
  File "/s/bach/j/under/mroseliu/.local/lib/python2.7/site-packages/pyedf/views.py", line 14, in <module>
    from colorker.service import bigquery, drive, fusiontables, gee
  File "/s/bach/j/under/mroseliu/.local/lib/python2.7/site-packages/colorker/service/bigquery.py", line 17, in <module>
    from colorker.security import CredentialManager
  File "/s/bach/j/under/mroseliu/.local/lib/python2.7/site-packages/colorker/security.py", line 7, in <module>
    import ee
  File "/s/bach/j/under/mroseliu/.local/lib/python2.7/site-packages/ee/__init__.py", line 18, in <module>
    from . import batch
  File "/s/bach/j/under/mroseliu/.local/lib/python2.7/site-packages/ee/batch.py", line 15, in <module>
    from . import data
  File "/s/bach/j/under/mroseliu/.local/lib/python2.7/site-packages/ee/data.py", line 14, in <module>
    import httplib2
ImportError: No module named httplib2
[20/Oct/2017 21:56:16] ERROR [django.request:284] Internal Server Error: /favicon.ico
Traceback (most recent call last):
  File "/s/bach/j/under/mroseliu/.local/lib/python2.7/site-packages/django/core/handlers/base.py", line 134, in get_response
    resolver_match = resolver.resolve(request.path_info)
  File "/s/bach/j/under/mroseliu/.local/lib/python2.7/site-packages/django/core/urlresolvers.py", line 374, in resolve
    for pattern in self.url_patterns:
  File "/s/bach/j/under/mroseliu/.local/lib/python2.7/site-packages/django/utils/functional.py", line 33, in __get__
    res = instance.__dict__[self.name] = self.func(instance)
  File "/s/bach/j/under/mroseliu/.local/lib/python2.7/site-packages/django/core/urlresolvers.py", line 417, in url_patterns
    patterns = getattr(self.urlconf_module, "urlpatterns", self.urlconf_module)
  File "/s/bach/j/under/mroseliu/.local/lib/python2.7/site-packages/django/utils/functional.py", line 33, in __get__
    res = instance.__dict__[self.name] = self.func(instance)
  File "/s/bach/j/under/mroseliu/.local/lib/python2.7/site-packages/django/core/urlresolvers.py", line 410, in urlconf_module
    return import_module(self.urlconf_name)
  File "/usr/lib64/python2.7/importlib/__init__.py", line 37, in import_module
    __import__(name)
  File "/s/bach/j/under/mroseliu/.local/lib/python2.7/site-packages/columbus/urls.py", line 20, in <module>
    from pyedf.views import *
  File "/s/bach/j/under/mroseliu/.local/lib/python2.7/site-packages/pyedf/views.py", line 14, in <module>
    from colorker.service import bigquery, drive, fusiontables, gee
  File "/s/bach/j/under/mroseliu/.local/lib/python2.7/site-packages/colorker/service/bigquery.py", line 17, in <module>
    from colorker.security import CredentialManager
  File "/s/bach/j/under/mroseliu/.local/lib/python2.7/site-packages/colorker/security.py", line 7, in <module>
    import ee
  File "/s/bach/j/under/mroseliu/.local/lib/python2.7/site-packages/ee/__init__.py", line 18, in <module>
    from . import batch
  File "/s/bach/j/under/mroseliu/.local/lib/python2.7/site-packages/ee/batch.py", line 15, in <module>
    from . import data
  File "/s/bach/j/under/mroseliu/.local/lib/python2.7/site-packages/ee/data.py", line 14, in <module>
    import httplib2
ImportError: No module named httplib2
[20/Oct/2017 22:10:45] ERROR [django.request:284] Internal Server Error: /
Traceback (most recent call last):
  File "/s/bach/j/under/mroseliu/.local/lib/python2.7/site-packages/django/core/handlers/base.py", line 134, in get_response
    resolver_match = resolver.resolve(request.path_info)
  File "/s/bach/j/under/mroseliu/.local/lib/python2.7/site-packages/django/core/urlresolvers.py", line 374, in resolve
    for pattern in self.url_patterns:
  File "/s/bach/j/under/mroseliu/.local/lib/python2.7/site-packages/django/utils/functional.py", line 33, in __get__
    res = instance.__dict__[self.name] = self.func(instance)
  File "/s/bach/j/under/mroseliu/.local/lib/python2.7/site-packages/django/core/urlresolvers.py", line 417, in url_patterns
    patterns = getattr(self.urlconf_module, "urlpatterns", self.urlconf_module)
  File "/s/bach/j/under/mroseliu/.local/lib/python2.7/site-packages/django/utils/functional.py", line 33, in __get__
    res = instance.__dict__[self.name] = self.func(instance)
  File "/s/bach/j/under/mroseliu/.local/lib/python2.7/site-packages/django/core/urlresolvers.py", line 410, in urlconf_module
    return import_module(self.urlconf_name)
  File "/usr/lib64/python2.7/importlib/__init__.py", line 37, in import_module
    __import__(name)
  File "/s/bach/j/under/mroseliu/.local/lib/python2.7/site-packages/columbus/urls.py", line 20, in <module>
    from pyedf.views import *
  File "/s/bach/j/under/mroseliu/.local/lib/python2.7/site-packages/pyedf/views.py", line 14, in <module>
    from colorker.service import bigquery, drive, fusiontables, gee
  File "/s/bach/j/under/mroseliu/.local/lib/python2.7/site-packages/colorker/service/bigquery.py", line 17, in <module>
    from colorker.security import CredentialManager
  File "/s/bach/j/under/mroseliu/.local/lib/python2.7/site-packages/colorker/security.py", line 7, in <module>
    import ee
  File "/s/bach/j/under/mroseliu/.local/lib/python2.7/site-packages/ee/__init__.py", line 18, in <module>
    from . import batch
  File "/s/bach/j/under/mroseliu/.local/lib/python2.7/site-packages/ee/batch.py", line 15, in <module>
    from . import data
  File "/s/bach/j/under/mroseliu/.local/lib/python2.7/site-packages/ee/data.py", line 14, in <module>
    import httplib2
ImportError: No module named httplib2
[20/Oct/2017 22:12:01] ERROR [django.request:284] Internal Server Error: /
Traceback (most recent call last):
  File "/s/bach/j/under/mroseliu/.local/lib/python2.7/site-packages/django/core/handlers/base.py", line 149, in get_response
    response = self.process_exception_by_middleware(e, request)
  File "/s/bach/j/under/mroseliu/.local/lib/python2.7/site-packages/django/core/handlers/base.py", line 147, in get_response
    response = wrapped_callback(request, *callback_args, **callback_kwargs)
  File "/s/bach/j/under/mroseliu/.local/lib/python2.7/site-packages/django/views/generic/base.py", line 68, in view
    return self.dispatch(request, *args, **kwargs)
  File "/s/bach/j/under/mroseliu/.local/lib/python2.7/site-packages/django/views/generic/base.py", line 88, in dispatch
    return handler(request, *args, **kwargs)
  File "/s/bach/j/under/mroseliu/.local/lib/python2.7/site-packages/pyedf/views.py", line 376, in get
    return render(request, str(page) + '.html', params)
  File "/s/bach/j/under/mroseliu/.local/lib/python2.7/site-packages/django/shortcuts.py", line 67, in render
    template_name, context, request=request, using=using)
  File "/s/bach/j/under/mroseliu/.local/lib/python2.7/site-packages/django/template/loader.py", line 96, in render_to_string
    template = get_template(template_name, using=using)
  File "/s/bach/j/under/mroseliu/.local/lib/python2.7/site-packages/django/template/loader.py", line 43, in get_template
    raise TemplateDoesNotExist(template_name, chain=chain)
TemplateDoesNotExist: nlhome.html
[20/Oct/2017 22:23:21] ERROR [django.request:284] Internal Server Error: /
Traceback (most recent call last):
  File "/s/bach/j/under/mroseliu/.local/lib/python2.7/site-packages/django/core/handlers/base.py", line 149, in get_response
    response = self.process_exception_by_middleware(e, request)
  File "/s/bach/j/under/mroseliu/.local/lib/python2.7/site-packages/django/core/handlers/base.py", line 147, in get_response
    response = wrapped_callback(request, *callback_args, **callback_kwargs)
  File "/s/bach/j/under/mroseliu/.local/lib/python2.7/site-packages/django/views/generic/base.py", line 68, in view
    return self.dispatch(request, *args, **kwargs)
  File "/s/bach/j/under/mroseliu/.local/lib/python2.7/site-packages/django/views/generic/base.py", line 88, in dispatch
    return handler(request, *args, **kwargs)
  File "/s/bach/j/under/mroseliu/.local/lib/python2.7/site-packages/pyedf/views.py", line 376, in get
    return render(request, str(page) + '.html', params)
  File "/s/bach/j/under/mroseliu/.local/lib/python2.7/site-packages/django/shortcuts.py", line 67, in render
    template_name, context, request=request, using=using)
  File "/s/bach/j/under/mroseliu/.local/lib/python2.7/site-packages/django/template/loader.py", line 96, in render_to_string
    template = get_template(template_name, using=using)
  File "/s/bach/j/under/mroseliu/.local/lib/python2.7/site-packages/django/template/loader.py", line 43, in get_template
    raise TemplateDoesNotExist(template_name, chain=chain)
TemplateDoesNotExist: nlhome.html
[20/Oct/2017 22:26:47] ERROR [django.request:284] Internal Server Error: /
Traceback (most recent call last):
  File "/s/bach/j/under/mroseliu/.local/lib/python2.7/site-packages/django/core/handlers/base.py", line 149, in get_response
    response = self.process_exception_by_middleware(e, request)
  File "/s/bach/j/under/mroseliu/.local/lib/python2.7/site-packages/django/core/handlers/base.py", line 147, in get_response
    response = wrapped_callback(request, *callback_args, **callback_kwargs)
  File "/s/bach/j/under/mroseliu/.local/lib/python2.7/site-packages/django/views/generic/base.py", line 68, in view
    return self.dispatch(request, *args, **kwargs)
  File "/s/bach/j/under/mroseliu/.local/lib/python2.7/site-packages/django/views/generic/base.py", line 88, in dispatch
    return handler(request, *args, **kwargs)
  File "/s/bach/j/under/mroseliu/.local/lib/python2.7/site-packages/pyedf/views.py", line 376, in get
    return render(request, str(page) + '.html', params)
  File "/s/bach/j/under/mroseliu/.local/lib/python2.7/site-packages/django/shortcuts.py", line 67, in render
    template_name, context, request=request, using=using)
  File "/s/bach/j/under/mroseliu/.local/lib/python2.7/site-packages/django/template/loader.py", line 96, in render_to_string
    template = get_template(template_name, using=using)
  File "/s/bach/j/under/mroseliu/.local/lib/python2.7/site-packages/django/template/loader.py", line 43, in get_template
    raise TemplateDoesNotExist(template_name, chain=chain)
TemplateDoesNotExist: nlhome.html
[23/Oct/2017 16:49:44] ERROR [django.request:284] Internal Server Error: /
Traceback (most recent call last):
  File "/s/bach/j/under/mroseliu/.local/lib/python2.7/site-packages/django/core/handlers/base.py", line 149, in get_response
    response = self.process_exception_by_middleware(e, request)
  File "/s/bach/j/under/mroseliu/.local/lib/python2.7/site-packages/django/core/handlers/base.py", line 147, in get_response
    response = wrapped_callback(request, *callback_args, **callback_kwargs)
  File "/s/bach/j/under/mroseliu/.local/lib/python2.7/site-packages/django/views/generic/base.py", line 68, in view
    return self.dispatch(request, *args, **kwargs)
  File "/s/bach/j/under/mroseliu/.local/lib/python2.7/site-packages/django/views/generic/base.py", line 88, in dispatch
    return handler(request, *args, **kwargs)
  File "/s/bach/j/under/mroseliu/.local/lib/python2.7/site-packages/pyedf/views.py", line 376, in get
    return render(request, str(page) + '.html', params)
  File "/s/bach/j/under/mroseliu/.local/lib/python2.7/site-packages/django/shortcuts.py", line 67, in render
    template_name, context, request=request, using=using)
  File "/s/bach/j/under/mroseliu/.local/lib/python2.7/site-packages/django/template/loader.py", line 96, in render_to_string
    template = get_template(template_name, using=using)
  File "/s/bach/j/under/mroseliu/.local/lib/python2.7/site-packages/django/template/loader.py", line 43, in get_template
    raise TemplateDoesNotExist(template_name, chain=chain)
TemplateDoesNotExist: index.html
[23/Oct/2017 16:49:44] ERROR [django.request:284] Internal Server Error: /
Traceback (most recent call last):
  File "/s/bach/j/under/mroseliu/.local/lib/python2.7/site-packages/django/core/handlers/base.py", line 149, in get_response
    response = self.process_exception_by_middleware(e, request)
  File "/s/bach/j/under/mroseliu/.local/lib/python2.7/site-packages/django/core/handlers/base.py", line 147, in get_response
    response = wrapped_callback(request, *callback_args, **callback_kwargs)
  File "/s/bach/j/under/mroseliu/.local/lib/python2.7/site-packages/django/views/generic/base.py", line 68, in view
    return self.dispatch(request, *args, **kwargs)
  File "/s/bach/j/under/mroseliu/.local/lib/python2.7/site-packages/django/views/generic/base.py", line 88, in dispatch
    return handler(request, *args, **kwargs)
  File "/s/bach/j/under/mroseliu/.local/lib/python2.7/site-packages/pyedf/views.py", line 376, in get
    return render(request, str(page) + '.html', params)
  File "/s/bach/j/under/mroseliu/.local/lib/python2.7/site-packages/django/shortcuts.py", line 67, in render
    template_name, context, request=request, using=using)
  File "/s/bach/j/under/mroseliu/.local/lib/python2.7/site-packages/django/template/loader.py", line 96, in render_to_string
    template = get_template(template_name, using=using)
  File "/s/bach/j/under/mroseliu/.local/lib/python2.7/site-packages/django/template/loader.py", line 43, in get_template
    raise TemplateDoesNotExist(template_name, chain=chain)
TemplateDoesNotExist: index.html
[23/Oct/2017 17:58:40] ERROR [django.request:284] Internal Server Error: /
Traceback (most recent call last):
  File "/s/bach/j/under/mroseliu/.local/lib/python2.7/site-packages/django/core/handlers/base.py", line 149, in get_response
    response = self.process_exception_by_middleware(e, request)
  File "/s/bach/j/under/mroseliu/.local/lib/python2.7/site-packages/django/core/handlers/base.py", line 147, in get_response
    response = wrapped_callback(request, *callback_args, **callback_kwargs)
  File "/s/bach/j/under/mroseliu/.local/lib/python2.7/site-packages/django/views/generic/base.py", line 68, in view
    return self.dispatch(request, *args, **kwargs)
  File "/s/bach/j/under/mroseliu/.local/lib/python2.7/site-packages/django/views/generic/base.py", line 88, in dispatch
    return handler(request, *args, **kwargs)
  File "/s/bach/j/under/mroseliu/.local/lib/python2.7/site-packages/pyedf/views.py", line 376, in get
    return render(request, str(page) + '.html', params)
  File "/s/bach/j/under/mroseliu/.local/lib/python2.7/site-packages/django/shortcuts.py", line 67, in render
    template_name, context, request=request, using=using)
  File "/s/bach/j/under/mroseliu/.local/lib/python2.7/site-packages/django/template/loader.py", line 96, in render_to_string
    template = get_template(template_name, using=using)
  File "/s/bach/j/under/mroseliu/.local/lib/python2.7/site-packages/django/template/loader.py", line 43, in get_template
    raise TemplateDoesNotExist(template_name, chain=chain)
TemplateDoesNotExist: index.html
[23/Oct/2017 18:30:38] ERROR [django.request:284] Internal Server Error: /
Traceback (most recent call last):
  File "/s/bach/j/under/mroseliu/.local/lib/python2.7/site-packages/django/core/handlers/base.py", line 149, in get_response
    response = self.process_exception_by_middleware(e, request)
  File "/s/bach/j/under/mroseliu/.local/lib/python2.7/site-packages/django/core/handlers/base.py", line 147, in get_response
    response = wrapped_callback(request, *callback_args, **callback_kwargs)
  File "/s/bach/j/under/mroseliu/.local/lib/python2.7/site-packages/django/views/generic/base.py", line 68, in view
    return self.dispatch(request, *args, **kwargs)
  File "/s/bach/j/under/mroseliu/.local/lib/python2.7/site-packages/django/views/generic/base.py", line 88, in dispatch
    return handler(request, *args, **kwargs)
  File "/s/bach/j/under/mroseliu/.local/lib/python2.7/site-packages/pyedf/views.py", line 376, in get
    return render(request, str(page) + '.html', params)
  File "/s/bach/j/under/mroseliu/.local/lib/python2.7/site-packages/django/shortcuts.py", line 67, in render
    template_name, context, request=request, using=using)
  File "/s/bach/j/under/mroseliu/.local/lib/python2.7/site-packages/django/template/loader.py", line 96, in render_to_string
    template = get_template(template_name, using=using)
  File "/s/bach/j/under/mroseliu/.local/lib/python2.7/site-packages/django/template/loader.py", line 43, in get_template
    raise TemplateDoesNotExist(template_name, chain=chain)
TemplateDoesNotExist: index.html
[23/Oct/2017 18:31:58] ERROR [django.request:284] Internal Server Error: /
Traceback (most recent call last):
  File "/s/bach/j/under/mroseliu/.local/lib/python2.7/site-packages/django/core/handlers/base.py", line 149, in get_response
    response = self.process_exception_by_middleware(e, request)
  File "/s/bach/j/under/mroseliu/.local/lib/python2.7/site-packages/django/core/handlers/base.py", line 147, in get_response
    response = wrapped_callback(request, *callback_args, **callback_kwargs)
  File "/s/bach/j/under/mroseliu/.local/lib/python2.7/site-packages/django/views/generic/base.py", line 68, in view
    return self.dispatch(request, *args, **kwargs)
  File "/s/bach/j/under/mroseliu/.local/lib/python2.7/site-packages/django/views/generic/base.py", line 88, in dispatch
    return handler(request, *args, **kwargs)
  File "/s/bach/j/under/mroseliu/.local/lib/python2.7/site-packages/pyedf/views.py", line 376, in get
    return render(request, str(page) + '.html', params)
  File "/s/bach/j/under/mroseliu/.local/lib/python2.7/site-packages/django/shortcuts.py", line 67, in render
    template_name, context, request=request, using=using)
  File "/s/bach/j/under/mroseliu/.local/lib/python2.7/site-packages/django/template/loader.py", line 96, in render_to_string
    template = get_template(template_name, using=using)
  File "/s/bach/j/under/mroseliu/.local/lib/python2.7/site-packages/django/template/loader.py", line 43, in get_template
    raise TemplateDoesNotExist(template_name, chain=chain)
TemplateDoesNotExist: index.html
[23/Oct/2017 18:32:05] ERROR [django.request:284] Internal Server Error: /
Traceback (most recent call last):
  File "/s/bach/j/under/mroseliu/.local/lib/python2.7/site-packages/django/core/handlers/base.py", line 149, in get_response
    response = self.process_exception_by_middleware(e, request)
  File "/s/bach/j/under/mroseliu/.local/lib/python2.7/site-packages/django/core/handlers/base.py", line 147, in get_response
    response = wrapped_callback(request, *callback_args, **callback_kwargs)
  File "/s/bach/j/under/mroseliu/.local/lib/python2.7/site-packages/django/views/generic/base.py", line 68, in view
    return self.dispatch(request, *args, **kwargs)
  File "/s/bach/j/under/mroseliu/.local/lib/python2.7/site-packages/django/views/generic/base.py", line 88, in dispatch
    return handler(request, *args, **kwargs)
  File "/s/bach/j/under/mroseliu/.local/lib/python2.7/site-packages/pyedf/views.py", line 376, in get
    return render(request, str(page) + '.html', params)
  File "/s/bach/j/under/mroseliu/.local/lib/python2.7/site-packages/django/shortcuts.py", line 67, in render
    template_name, context, request=request, using=using)
  File "/s/bach/j/under/mroseliu/.local/lib/python2.7/site-packages/django/template/loader.py", line 96, in render_to_string
    template = get_template(template_name, using=using)
  File "/s/bach/j/under/mroseliu/.local/lib/python2.7/site-packages/django/template/loader.py", line 43, in get_template
    raise TemplateDoesNotExist(template_name, chain=chain)
TemplateDoesNotExist: index.html
[23/Oct/2017 18:33:31] ERROR [django.request:284] Internal Server Error: /
Traceback (most recent call last):
  File "/s/bach/j/under/mroseliu/.local/lib/python2.7/site-packages/django/core/handlers/base.py", line 149, in get_response
    response = self.process_exception_by_middleware(e, request)
  File "/s/bach/j/under/mroseliu/.local/lib/python2.7/site-packages/django/core/handlers/base.py", line 147, in get_response
    response = wrapped_callback(request, *callback_args, **callback_kwargs)
  File "/s/bach/j/under/mroseliu/.local/lib/python2.7/site-packages/django/views/generic/base.py", line 68, in view
    return self.dispatch(request, *args, **kwargs)
  File "/s/bach/j/under/mroseliu/.local/lib/python2.7/site-packages/django/views/generic/base.py", line 88, in dispatch
    return handler(request, *args, **kwargs)
  File "/s/bach/j/under/mroseliu/.local/lib/python2.7/site-packages/pyedf/views.py", line 376, in get
    return render(request, str(page) + '.html', params)
  File "/s/bach/j/under/mroseliu/.local/lib/python2.7/site-packages/django/shortcuts.py", line 67, in render
    template_name, context, request=request, using=using)
  File "/s/bach/j/under/mroseliu/.local/lib/python2.7/site-packages/django/template/loader.py", line 96, in render_to_string
    template = get_template(template_name, using=using)
  File "/s/bach/j/under/mroseliu/.local/lib/python2.7/site-packages/django/template/loader.py", line 43, in get_template
    raise TemplateDoesNotExist(template_name, chain=chain)
TemplateDoesNotExist: index.html
[23/Oct/2017 18:34:16] ERROR [django.request:284] Internal Server Error: /
Traceback (most recent call last):
  File "/s/bach/j/under/mroseliu/.local/lib/python2.7/site-packages/django/core/handlers/base.py", line 149, in get_response
    response = self.process_exception_by_middleware(e, request)
  File "/s/bach/j/under/mroseliu/.local/lib/python2.7/site-packages/django/core/handlers/base.py", line 147, in get_response
    response = wrapped_callback(request, *callback_args, **callback_kwargs)
  File "/s/bach/j/under/mroseliu/.local/lib/python2.7/site-packages/django/views/generic/base.py", line 68, in view
    return self.dispatch(request, *args, **kwargs)
  File "/s/bach/j/under/mroseliu/.local/lib/python2.7/site-packages/django/views/generic/base.py", line 88, in dispatch
    return handler(request, *args, **kwargs)
  File "/s/bach/j/under/mroseliu/.local/lib/python2.7/site-packages/pyedf/views.py", line 376, in get
    return render(request, str(page) + '.html', params)
  File "/s/bach/j/under/mroseliu/.local/lib/python2.7/site-packages/django/shortcuts.py", line 67, in render
    template_name, context, request=request, using=using)
  File "/s/bach/j/under/mroseliu/.local/lib/python2.7/site-packages/django/template/loader.py", line 96, in render_to_string
    template = get_template(template_name, using=using)
  File "/s/bach/j/under/mroseliu/.local/lib/python2.7/site-packages/django/template/loader.py", line 43, in get_template
    raise TemplateDoesNotExist(template_name, chain=chain)
TemplateDoesNotExist: index.html
[23/Oct/2017 18:38:42] ERROR [django.request:284] Internal Server Error: /
Traceback (most recent call last):
  File "/s/bach/j/under/mroseliu/.local/lib/python2.7/site-packages/django/core/handlers/base.py", line 149, in get_response
    response = self.process_exception_by_middleware(e, request)
  File "/s/bach/j/under/mroseliu/.local/lib/python2.7/site-packages/django/core/handlers/base.py", line 147, in get_response
    response = wrapped_callback(request, *callback_args, **callback_kwargs)
  File "/s/bach/j/under/mroseliu/.local/lib/python2.7/site-packages/django/views/generic/base.py", line 68, in view
    return self.dispatch(request, *args, **kwargs)
  File "/s/bach/j/under/mroseliu/.local/lib/python2.7/site-packages/django/views/generic/base.py", line 88, in dispatch
    return handler(request, *args, **kwargs)
  File "/s/bach/j/under/mroseliu/.local/lib/python2.7/site-packages/pyedf/views.py", line 376, in get
    return render(request, str(page) + '.html', params)
  File "/s/bach/j/under/mroseliu/.local/lib/python2.7/site-packages/django/shortcuts.py", line 67, in render
    template_name, context, request=request, using=using)
  File "/s/bach/j/under/mroseliu/.local/lib/python2.7/site-packages/django/template/loader.py", line 96, in render_to_string
    template = get_template(template_name, using=using)
  File "/s/bach/j/under/mroseliu/.local/lib/python2.7/site-packages/django/template/loader.py", line 43, in get_template
    raise TemplateDoesNotExist(template_name, chain=chain)
TemplateDoesNotExist: index.html
[23/Oct/2017 18:47:39] ERROR [django.request:284] Internal Server Error: /
Traceback (most recent call last):
  File "/s/bach/j/under/mroseliu/.local/lib/python2.7/site-packages/django/core/handlers/base.py", line 149, in get_response
    response = self.process_exception_by_middleware(e, request)
  File "/s/bach/j/under/mroseliu/.local/lib/python2.7/site-packages/django/core/handlers/base.py", line 147, in get_response
    response = wrapped_callback(request, *callback_args, **callback_kwargs)
  File "/s/bach/j/under/mroseliu/.local/lib/python2.7/site-packages/django/views/generic/base.py", line 68, in view
    return self.dispatch(request, *args, **kwargs)
  File "/s/bach/j/under/mroseliu/.local/lib/python2.7/site-packages/django/views/generic/base.py", line 88, in dispatch
    return handler(request, *args, **kwargs)
  File "/s/bach/j/under/mroseliu/.local/lib/python2.7/site-packages/pyedf/views.py", line 376, in get
    return render(request, str(page) + '.html', params)
  File "/s/bach/j/under/mroseliu/.local/lib/python2.7/site-packages/django/shortcuts.py", line 67, in render
    template_name, context, request=request, using=using)
  File "/s/bach/j/under/mroseliu/.local/lib/python2.7/site-packages/django/template/loader.py", line 96, in render_to_string
    template = get_template(template_name, using=using)
  File "/s/bach/j/under/mroseliu/.local/lib/python2.7/site-packages/django/template/loader.py", line 43, in get_template
    raise TemplateDoesNotExist(template_name, chain=chain)
TemplateDoesNotExist: index.html
[23/Oct/2017 18:48:55] ERROR [django.request:284] Internal Server Error: /
Traceback (most recent call last):
  File "/s/bach/j/under/mroseliu/.local/lib/python2.7/site-packages/django/core/handlers/base.py", line 149, in get_response
    response = self.process_exception_by_middleware(e, request)
  File "/s/bach/j/under/mroseliu/.local/lib/python2.7/site-packages/django/core/handlers/base.py", line 147, in get_response
    response = wrapped_callback(request, *callback_args, **callback_kwargs)
  File "/s/bach/j/under/mroseliu/.local/lib/python2.7/site-packages/django/views/generic/base.py", line 68, in view
    return self.dispatch(request, *args, **kwargs)
  File "/s/bach/j/under/mroseliu/.local/lib/python2.7/site-packages/django/views/generic/base.py", line 88, in dispatch
    return handler(request, *args, **kwargs)
  File "/s/bach/j/under/mroseliu/.local/lib/python2.7/site-packages/pyedf/views.py", line 376, in get
    return render(request, str(page) + '.html', params)
  File "/s/bach/j/under/mroseliu/.local/lib/python2.7/site-packages/django/shortcuts.py", line 67, in render
    template_name, context, request=request, using=using)
  File "/s/bach/j/under/mroseliu/.local/lib/python2.7/site-packages/django/template/loader.py", line 96, in render_to_string
    template = get_template(template_name, using=using)
  File "/s/bach/j/under/mroseliu/.local/lib/python2.7/site-packages/django/template/loader.py", line 43, in get_template
    raise TemplateDoesNotExist(template_name, chain=chain)
TemplateDoesNotExist: index.html
[23/Oct/2017 19:00:51] ERROR [django.request:284] Internal Server Error: /
Traceback (most recent call last):
  File "/s/bach/j/under/mroseliu/.local/lib/python2.7/site-packages/django/core/handlers/base.py", line 149, in get_response
    response = self.process_exception_by_middleware(e, request)
  File "/s/bach/j/under/mroseliu/.local/lib/python2.7/site-packages/django/core/handlers/base.py", line 147, in get_response
    response = wrapped_callback(request, *callback_args, **callback_kwargs)
  File "/s/bach/j/under/mroseliu/.local/lib/python2.7/site-packages/django/views/generic/base.py", line 68, in view
    return self.dispatch(request, *args, **kwargs)
  File "/s/bach/j/under/mroseliu/.local/lib/python2.7/site-packages/django/views/generic/base.py", line 88, in dispatch
    return handler(request, *args, **kwargs)
  File "/s/bach/j/under/mroseliu/.local/lib/python2.7/site-packages/pyedf/views.py", line 376, in get
    return render(request, str(page) + '.html', params)
  File "/s/bach/j/under/mroseliu/.local/lib/python2.7/site-packages/django/shortcuts.py", line 67, in render
    template_name, context, request=request, using=using)
  File "/s/bach/j/under/mroseliu/.local/lib/python2.7/site-packages/django/template/loader.py", line 96, in render_to_string
    template = get_template(template_name, using=using)
  File "/s/bach/j/under/mroseliu/.local/lib/python2.7/site-packages/django/template/loader.py", line 43, in get_template
    raise TemplateDoesNotExist(template_name, chain=chain)
TemplateDoesNotExist: index.html
[23/Oct/2017 19:01:09] ERROR [django.request:284] Internal Server Error: /
Traceback (most recent call last):
  File "/s/bach/j/under/mroseliu/.local/lib/python2.7/site-packages/django/core/handlers/base.py", line 149, in get_response
    response = self.process_exception_by_middleware(e, request)
  File "/s/bach/j/under/mroseliu/.local/lib/python2.7/site-packages/django/core/handlers/base.py", line 147, in get_response
    response = wrapped_callback(request, *callback_args, **callback_kwargs)
  File "/s/bach/j/under/mroseliu/.local/lib/python2.7/site-packages/django/views/generic/base.py", line 68, in view
    return self.dispatch(request, *args, **kwargs)
  File "/s/bach/j/under/mroseliu/.local/lib/python2.7/site-packages/django/views/generic/base.py", line 88, in dispatch
    return handler(request, *args, **kwargs)
  File "/s/bach/j/under/mroseliu/.local/lib/python2.7/site-packages/pyedf/views.py", line 376, in get
    return render(request, str(page) + '.html', params)
  File "/s/bach/j/under/mroseliu/.local/lib/python2.7/site-packages/django/shortcuts.py", line 67, in render
    template_name, context, request=request, using=using)
  File "/s/bach/j/under/mroseliu/.local/lib/python2.7/site-packages/django/template/loader.py", line 96, in render_to_string
    template = get_template(template_name, using=using)
  File "/s/bach/j/under/mroseliu/.local/lib/python2.7/site-packages/django/template/loader.py", line 43, in get_template
    raise TemplateDoesNotExist(template_name, chain=chain)
TemplateDoesNotExist: index.html
[23/Oct/2017 19:02:30] ERROR [django.request:284] Internal Server Error: /
Traceback (most recent call last):
  File "/s/bach/j/under/mroseliu/.local/lib/python2.7/site-packages/django/core/handlers/base.py", line 149, in get_response
    response = self.process_exception_by_middleware(e, request)
  File "/s/bach/j/under/mroseliu/.local/lib/python2.7/site-packages/django/core/handlers/base.py", line 147, in get_response
    response = wrapped_callback(request, *callback_args, **callback_kwargs)
  File "/s/bach/j/under/mroseliu/.local/lib/python2.7/site-packages/django/views/generic/base.py", line 68, in view
    return self.dispatch(request, *args, **kwargs)
  File "/s/bach/j/under/mroseliu/.local/lib/python2.7/site-packages/django/views/generic/base.py", line 88, in dispatch
    return handler(request, *args, **kwargs)
  File "/s/bach/j/under/mroseliu/.local/lib/python2.7/site-packages/pyedf/views.py", line 376, in get
    return render(request, str(page) + '.html', params)
  File "/s/bach/j/under/mroseliu/.local/lib/python2.7/site-packages/django/shortcuts.py", line 67, in render
    template_name, context, request=request, using=using)
  File "/s/bach/j/under/mroseliu/.local/lib/python2.7/site-packages/django/template/loader.py", line 96, in render_to_string
    template = get_template(template_name, using=using)
  File "/s/bach/j/under/mroseliu/.local/lib/python2.7/site-packages/django/template/loader.py", line 43, in get_template
    raise TemplateDoesNotExist(template_name, chain=chain)
TemplateDoesNotExist: index.html
[23/Oct/2017 19:03:45] ERROR [django.request:284] Internal Server Error: /
Traceback (most recent call last):
  File "/s/bach/j/under/mroseliu/.local/lib/python2.7/site-packages/django/core/handlers/base.py", line 149, in get_response
    response = self.process_exception_by_middleware(e, request)
  File "/s/bach/j/under/mroseliu/.local/lib/python2.7/site-packages/django/core/handlers/base.py", line 147, in get_response
    response = wrapped_callback(request, *callback_args, **callback_kwargs)
  File "/s/bach/j/under/mroseliu/.local/lib/python2.7/site-packages/django/views/generic/base.py", line 68, in view
    return self.dispatch(request, *args, **kwargs)
  File "/s/bach/j/under/mroseliu/.local/lib/python2.7/site-packages/django/views/generic/base.py", line 88, in dispatch
    return handler(request, *args, **kwargs)
  File "/s/bach/j/under/mroseliu/.local/lib/python2.7/site-packages/pyedf/views.py", line 376, in get
    return render(request, str(page) + '.html', params)
  File "/s/bach/j/under/mroseliu/.local/lib/python2.7/site-packages/django/shortcuts.py", line 67, in render
    template_name, context, request=request, using=using)
  File "/s/bach/j/under/mroseliu/.local/lib/python2.7/site-packages/django/template/loader.py", line 96, in render_to_string
    template = get_template(template_name, using=using)
  File "/s/bach/j/under/mroseliu/.local/lib/python2.7/site-packages/django/template/loader.py", line 43, in get_template
    raise TemplateDoesNotExist(template_name, chain=chain)
TemplateDoesNotExist: index.html
[23/Oct/2017 19:04:34] ERROR [django.request:284] Internal Server Error: /
Traceback (most recent call last):
  File "/s/bach/j/under/mroseliu/.local/lib/python2.7/site-packages/django/core/handlers/base.py", line 149, in get_response
    response = self.process_exception_by_middleware(e, request)
  File "/s/bach/j/under/mroseliu/.local/lib/python2.7/site-packages/django/core/handlers/base.py", line 147, in get_response
    response = wrapped_callback(request, *callback_args, **callback_kwargs)
  File "/s/bach/j/under/mroseliu/.local/lib/python2.7/site-packages/django/views/generic/base.py", line 68, in view
    return self.dispatch(request, *args, **kwargs)
  File "/s/bach/j/under/mroseliu/.local/lib/python2.7/site-packages/django/views/generic/base.py", line 88, in dispatch
    return handler(request, *args, **kwargs)
  File "/s/bach/j/under/mroseliu/.local/lib/python2.7/site-packages/pyedf/views.py", line 376, in get
    return render(request, str(page) + '.html', params)
  File "/s/bach/j/under/mroseliu/.local/lib/python2.7/site-packages/django/shortcuts.py", line 67, in render
    template_name, context, request=request, using=using)
  File "/s/bach/j/under/mroseliu/.local/lib/python2.7/site-packages/django/template/loader.py", line 96, in render_to_string
    template = get_template(template_name, using=using)
  File "/s/bach/j/under/mroseliu/.local/lib/python2.7/site-packages/django/template/loader.py", line 43, in get_template
    raise TemplateDoesNotExist(template_name, chain=chain)
TemplateDoesNotExist: index.html
[23/Oct/2017 19:05:06] ERROR [django.request:284] Internal Server Error: /
Traceback (most recent call last):
  File "/s/bach/j/under/mroseliu/.local/lib/python2.7/site-packages/django/core/handlers/base.py", line 149, in get_response
    response = self.process_exception_by_middleware(e, request)
  File "/s/bach/j/under/mroseliu/.local/lib/python2.7/site-packages/django/core/handlers/base.py", line 147, in get_response
    response = wrapped_callback(request, *callback_args, **callback_kwargs)
  File "/s/bach/j/under/mroseliu/.local/lib/python2.7/site-packages/django/views/generic/base.py", line 68, in view
    return self.dispatch(request, *args, **kwargs)
  File "/s/bach/j/under/mroseliu/.local/lib/python2.7/site-packages/django/views/generic/base.py", line 88, in dispatch
    return handler(request, *args, **kwargs)
  File "/s/bach/j/under/mroseliu/.local/lib/python2.7/site-packages/pyedf/views.py", line 376, in get
    return render(request, str(page) + '.html', params)
  File "/s/bach/j/under/mroseliu/.local/lib/python2.7/site-packages/django/shortcuts.py", line 67, in render
    template_name, context, request=request, using=using)
  File "/s/bach/j/under/mroseliu/.local/lib/python2.7/site-packages/django/template/loader.py", line 96, in render_to_string
    template = get_template(template_name, using=using)
  File "/s/bach/j/under/mroseliu/.local/lib/python2.7/site-packages/django/template/loader.py", line 43, in get_template
    raise TemplateDoesNotExist(template_name, chain=chain)
TemplateDoesNotExist: index.html
[23/Oct/2017 19:06:35] ERROR [django.request:284] Internal Server Error: /
Traceback (most recent call last):
  File "/s/bach/j/under/mroseliu/.local/lib/python2.7/site-packages/django/core/handlers/base.py", line 149, in get_response
    response = self.process_exception_by_middleware(e, request)
  File "/s/bach/j/under/mroseliu/.local/lib/python2.7/site-packages/django/core/handlers/base.py", line 147, in get_response
    response = wrapped_callback(request, *callback_args, **callback_kwargs)
  File "/s/bach/j/under/mroseliu/.local/lib/python2.7/site-packages/django/views/generic/base.py", line 68, in view
    return self.dispatch(request, *args, **kwargs)
  File "/s/bach/j/under/mroseliu/.local/lib/python2.7/site-packages/django/views/generic/base.py", line 88, in dispatch
    return handler(request, *args, **kwargs)
  File "/s/bach/j/under/mroseliu/.local/lib/python2.7/site-packages/pyedf/views.py", line 376, in get
    return render(request, str(page) + '.html', params)
  File "/s/bach/j/under/mroseliu/.local/lib/python2.7/site-packages/django/shortcuts.py", line 67, in render
    template_name, context, request=request, using=using)
  File "/s/bach/j/under/mroseliu/.local/lib/python2.7/site-packages/django/template/loader.py", line 96, in render_to_string
    template = get_template(template_name, using=using)
  File "/s/bach/j/under/mroseliu/.local/lib/python2.7/site-packages/django/template/loader.py", line 43, in get_template
    raise TemplateDoesNotExist(template_name, chain=chain)
TemplateDoesNotExist: nlhome.html
